PROCESS TOOK 2400 SECONDS ERROR in  benchmark_MACE.py  AND DSNAME  12 FOR C 1 AND ROW 1
PROCESS TOOK 2400 SECONDS ERROR in  benchmark_MACE.py  AND DSNAME  12 FOR C 1 AND ROW 0
